<?xml version="1.0"?>
<robot xmlns:xacro="http://www.ros.org/wiki/xacro">
    <xacro:macro name="wheel_x" params="name h r m">
        <link name="${name}">
            <inertial>
              <mass value="${m}"/>
              <origin rpy="0 0 0" xyz="0 0 0"/>
              <inertia ixx="${m*(3*r*r+h*h)/12}" ixy="0" ixz="0" iyy="${m*(3*r*r+h*h)/12}" iyz="0" izz="${m*(r*r)/4}"/>
            </inertial>
            <collision name="${name}_collision">
              <origin rpy="0 1.57079 0" xyz="0 0 0"/>
              <geometry>
               <cylinder length="${h}" radius="${r}"/>
              </geometry>
            </collision>
            <visual name="${name}_visual">
              <origin rpy="0 1.57079 0" xyz="0 0 0"/>
              <geometry>
                <cylinder length="${h}" radius="${r}"/>
              </geometry>
            </visual>
        </link>
    </xacro:macro>
    <xacro:macro name="wheel_y" params="name h r m">
        <link name="${name}">
            <inertial>
              <mass value="${m}"/>
              <origin rpy="0 0 0" xyz="0 0 0"/>
              <inertia ixx="${m*(3*r*r+h*h)/12}" ixy="0" ixz="0" iyy="${m*(3*r*r+h*h)/12}" iyz="0" izz="${m*(r*r)/4}"/>
            </inertial>
            <collision name="${name}_collision">
              <origin rpy="0 1.57079 1.57079" xyz="0 0 0"/>
              <geometry>
               <cylinder length="${h}" radius="${r}"/>
              </geometry>
            </collision>
            <visual name="${name}_visual">
              <origin rpy="0 1.57079 1.57079" xyz="0 0 0"/>
              <geometry>
                <cylinder length="${h}" radius="${r}"/>
              </geometry>
            </visual>
        </link>
    </xacro:macro>

    <xacro:macro name="joint_wheel_x" params="name parent child origin_xyz">
      <joint name="${name}" type="continuous">
        <origin rpy="0 0 0" xyz="${origin_xyz}"/>
        <child link="${child}"/>
        <parent link="${parent}"/>
        <axis rpy="0 0 0" xyz="1 0 0"/>
        <limit effort="10000" velocity="1000"/>
        <joint_properties damping="1.0" friction="1.0"/>
      </joint>
    </xacro:macro>

    <xacro:macro name="joint_wheel_y" params="name parent child origin_xyz">
      <joint name="${name}" type="continuous">
        <origin rpy="0 0 0" xyz="${origin_xyz}"/>
        <child link="${child}"/>
        <parent link="${parent}"/>
        <axis rpy="0 0 0" xyz="0 1 0"/>
        <limit effort="10000" velocity="1000"/>
        <joint_properties damping="1.0" friction="1.0"/>
      </joint>
    </xacro:macro>

</robot>